<?xml version="1.0" ?>
<!-- =================================================================================== -->
<!-- |    This document was autogenerated by xacro from ./core/nextage_description/urdf/NextageOpenObj.urdf | -->
<!-- |    EDITING THIS FILE BY HAND IS NOT RECOMMENDED                                 | -->
<!-- =================================================================================== -->
<robot name="NextageOpen" xmlns:body="http://playerstage.sourceforge.net/gazebo/xmlschema/#body" xmlns:controller="http://playerstage.sourceforge.net/gazebo/xmlschema/#controller" xmlns:gazebo="http://playerstage.sourceforge.net/gazebo/xmlschema/#gz" xmlns:geom="http://playerstage.sourceforge.net/gazebo/xmlschema/#geom" xmlns:interface="http://playerstage.sourceforge.net/gazebo/xmlschema/#interface" xmlns:joint="http://playerstage.sourceforge.net/gazebo/xmlschema/#joint" xmlns:model="http://playerstage.sourceforge.net/gazebo/xmlschema/#model" xmlns:physics="http://playerstage.sourceforge.net/gazebo/xmlschema/#physics" xmlns:renderable="http://playerstage.sourceforge.net/gazebo/xmlschema/#renderable" xmlns:rendering="http://playerstage.sourceforge.net/gazebo/xmlschema/#rendering" xmlns:sensor="http://playerstage.sourceforge.net/gazebo/xmlschema/#sensor" xmlns:xi="http://www.w3.org/2001/XInclude">
  <material name="Black">
    <color rgba="0.0 0.0 0.0 1.0"/>
  </material>
  <material name="Blue">
    <color rgba="0.0 0.0 0.8 1.0"/>
  </material>
  <material name="Green">
    <color rgba="0.0 0.8 0.0 1.0"/>
  </material>
  <material name="LightGrey">
    <color rgba="0.6 0.6 0.6 1.0"/>
  </material>
  <material name="Grey">
    <color rgba="0.4 0.4 0.4 1.0"/>
  </material>
  <material name="DarkGrey">
    <color rgba="0.2 0.2 0.2 1.0"/>
  </material>
  <material name="Red">
    <color rgba="0.8 0.0 0.0 1.0"/>
  </material>
  <material name="White">
    <color rgba="1.0 1.0 1.0 1.0"/>
  </material>
  <gazebo reference="gazebo_WAIST">
    <material>Gazebo/Black</material>
  </gazebo>
  <link name="WAIST">
    <visual>
      <origin rpy="0 -0 0" xyz="0 0 0.97"/>
      <geometry>
        <mesh filename="package://nextage_description/urdf/meshes/WAIST_Link_mesh.obj" scale="1 1 1"/>
      </geometry>
    </visual>
    <collision>
      <origin rpy="0 -0 0" xyz="0 0 0.97"/>
      <geometry>
        <mesh filename="package://nextage_description/urdf/meshes/WAIST_Link_mesh.obj" scale="1 1 1"/>
      </geometry>
    </collision>
    <inertial>
      <mass value="1000"/>
      <origin rpy="0 -0 0" xyz="0 0 0"/>
      <inertia ixx="20" ixy="0" ixz="0" iyy="20" iyz="0" izz="20"/>
    </inertial>
  </link>
  <gazebo reference="gazebo_CHEST_JOINT0_Link">
    <material>Gazebo/Black</material>
  </gazebo>
  <link name="CHEST_JOINT0_Link">
    <visual>
      <origin rpy="0 -0 0" xyz="0 0 0"/>
      <geometry>
        <mesh filename="package://nextage_description/urdf/meshes/CHEST_JOINT0_Link_mesh.obj" scale="1 1 1"/>
      </geometry>
    </visual>
    <collision>
      <origin rpy="0 -0 0" xyz="0 0 0"/>
      <geometry>
        <mesh filename="package://nextage_description/urdf/meshes/CHEST_JOINT0_Link_mesh.obj" scale="1 1 1"/>
      </geometry>
    </collision>
    <inertial>
      <mass value="3.0"/>
      <origin rpy="0 -0 0" xyz="0 0 0"/>
      <inertia ixx="0.0639575" ixy="-0.00022833" ixz="0.00011172" iyy="0.0310845" iyz="6.48e-05" izz="0.0501107"/>
    </inertial>
  </link>
  <gazebo reference="gazebo_HEAD_JOINT0_Link">
    <material>Gazebo/Black</material>
  </gazebo>
  <link name="HEAD_JOINT0_Link">
    <visual>
      <origin rpy="0 -0 0" xyz="0 0 0.5695"/>
      <geometry>
        <mesh filename="package://nextage_description/urdf/meshes/HEAD_JOINT0_Link_mesh.obj" scale="1 1 1"/>
      </geometry>
    </visual>
    <collision>
      <origin rpy="0 -0 0" xyz="0 0 0.5695"/>
      <geometry>
        <mesh filename="package://nextage_description/urdf/meshes/HEAD_JOINT0_Link_mesh.obj" scale="1 1 1"/>
      </geometry>
    </collision>
    <inertial>
      <mass value="0.317929"/>
      <origin rpy="0 -0 0" xyz="-2.292e-05 0.00547848 -0.00784016"/>
      <inertia ixx="0.00027682" ixy="3e-08" ixz="-3.3e-07" iyy="0.00013009" iyz="-1.092e-05" izz="0.00020954"/>
    </inertial>
  </link>
  <gazebo reference="gazebo_HEAD_JOINT1_Link">
    <material>Gazebo/Black</material>
  </gazebo>
  <link name="HEAD_JOINT1_Link">
    <visual>
      <origin rpy="0 -0 0" xyz="0 0 0"/>
      <geometry>
        <mesh filename="package://nextage_description/urdf/meshes/HEAD_JOINT1_Link_mesh.obj" scale="1 1 1"/>
      </geometry>
    </visual>
    <collision>
      <origin rpy="0 -0 0" xyz="0 0 0"/>
      <geometry>
        <mesh filename="package://nextage_description/urdf/meshes/HEAD_JOINT1_Link_mesh.obj" scale="1 1 1"/>
      </geometry>
    </collision>
    <inertial>
      <mass value="0.0808593"/>
      <!-- <origin xyz="5.02e-06 -0.0166777 0.0163153" rpy="0 -0 0"/> -->
      <!-- <inertia ixx="8.07e-05" ixy="-3e-08" ixz="-4.30134e-22" iyy="3.025e-05" iyz="-1.277e-05" izz="6.637e-05"/> -->
      <inertia ixx="1e-3" ixy="0" ixz="0" iyy="1e-3" iyz="0" izz="1e-3"/>
    </inertial>
  </link>
  <gazebo reference="gazebo_LARM_JOINT0_Link">
    <material>Gazebo/Black</material>
  </gazebo>
  <link name="LARM_JOINT0_Link">
    <visual>
      <origin rpy="-0.261799 0 0" xyz="0 0.145 0.370296"/>
      <geometry>
        <mesh filename="package://nextage_description/urdf/meshes/LARM_JOINT0_Link_mesh.obj" scale="1 1 1"/>
      </geometry>
    </visual>
    <collision>
      <origin rpy="-0.261799 0 0" xyz="0 0.145 0.370296"/>
      <geometry>
        <mesh filename="package://nextage_description/urdf/meshes/LARM_JOINT0_Link_mesh.obj" scale="1 1 1"/>
      </geometry>
    </collision>
    <inertial>
      <mass value="1.32626"/>
      <origin rpy="0 -0 0" xyz="-0.00226388 -0.00521383 0.0156081"/>
      <inertia ixx="0.00207537" ixy="0.00011276" ixz="8.927e-05" iyy="0.00240295" iyz="-4.57e-05" izz="0.00141912"/>
    </inertial>
  </link>
  <gazebo reference="gazebo_LARM_JOINT1_Link">
    <material>Gazebo/Black</material>
  </gazebo>
  <link name="LARM_JOINT1_Link">
    <visual>
      <origin rpy="0 -0 0" xyz="0 0 0"/>
      <geometry>
        <mesh filename="package://nextage_description/urdf/meshes/LARM_JOINT1_Link_mesh.obj" scale="1 1 1"/>
      </geometry>
    </visual>
    <collision>
      <origin rpy="0 -0 0" xyz="0 0 0"/>
      <geometry>
        <mesh filename="package://nextage_description/urdf/meshes/LARM_JOINT1_Link_mesh.obj" scale="1 1 1"/>
      </geometry>
    </collision>
    <inertial>
      <mass value="1.14898"/>
      <origin rpy="0 -0 0" xyz="-5.236e-05 0.0583134 -0.107061"/>
      <inertia ixx="0.0154168" ixy="9.95417e-07" ixz="3.38147e-06" iyy="0.0147117" iyz="0.00213719" izz="0.0012658"/>
    </inertial>
  </link>
  <gazebo reference="gazebo_LARM_JOINT2_Link">
    <material>Gazebo/Black</material>
  </gazebo>
  <link name="LARM_JOINT2_Link">
    <visual>
      <origin rpy="0 -0 0" xyz="0 0.095 -0.25"/>
      <geometry>
        <mesh filename="package://nextage_description/urdf/meshes/LARM_JOINT2_Link_mesh.obj" scale="1 1 1"/>
      </geometry>
    </visual>
    <collision>
      <origin rpy="0 -0 0" xyz="0 0.095 -0.25"/>
      <geometry>
        <mesh filename="package://nextage_description/urdf/meshes/LARM_JOINT2_Link_mesh.obj" scale="1 1 1"/>
      </geometry>
    </collision>
    <inertial>
      <mass value="0.577518"/>
      <origin rpy="0 -0 0" xyz="-2.254e-05 0.00167107 -0.0715116"/>
      <inertia ixx="0.00143966" ixy="-3e-07" ixz="1.2e-06" iyy="0.00141763" iyz="-7.596e-05" izz="0.0001972"/>
    </inertial>
  </link>
  <gazebo reference="gazebo_LARM_JOINT3_Link">
    <material>Gazebo/Black</material>
  </gazebo>
  <link name="LARM_JOINT3_Link">
    <visual>
      <origin rpy="0 -0 0" xyz="-0.03 0 0"/>
      <geometry>
        <mesh filename="package://nextage_description/urdf/meshes/LARM_JOINT3_Link_mesh.obj" scale="1 1 1"/>
      </geometry>
    </visual>
    <collision>
      <origin rpy="0 -0 0" xyz="-0.03 0 0"/>
      <geometry>
        <mesh filename="package://nextage_description/urdf/meshes/LARM_JOINT3_Link_mesh.obj" scale="1 1 1"/>
      </geometry>
    </collision>
    <inertial>
      <mass value="0.457418"/>
      <origin rpy="0 -0 0" xyz="-1.788e-05 -0.00395812 -0.20273"/>
      <inertia ixx="0.00069205" ixy="3e-08" ixz="5.2e-07" iyy="0.00068903" iyz="-1.915e-05" izz="0.00013509"/>
    </inertial>
  </link>
  <gazebo reference="gazebo_LARM_JOINT4_Link">
    <material>Gazebo/Black</material>
  </gazebo>
  <link name="LARM_JOINT4_Link">
    <visual>
      <origin rpy="0 -0 0" xyz="0 0 -0.235"/>
      <geometry>
        <mesh filename="package://nextage_description/urdf/meshes/LARM_JOINT4_Link_mesh.obj" scale="1 1 1"/>
      </geometry>
    </visual>
    <collision>
      <origin rpy="0 -0 0" xyz="0 0 -0.235"/>
      <geometry>
        <mesh filename="package://nextage_description/urdf/meshes/LARM_JOINT4_Link_mesh.obj" scale="1 1 1"/>
      </geometry>
    </collision>
    <inertial>
      <mass value="0.418434"/>
      <origin rpy="0 -0 0" xyz="0.00243131 0.00379733 -0.0577036"/>
      <inertia ixx="0.00052016" ixy="1.69e-06" ixz="7.9e-06" iyy="0.00050569" iyz="-5.377e-05" izz="0.00014004"/>
    </inertial>
  </link>
  <gazebo reference="gazebo_LARM_JOINT5_Link">
    <material>Gazebo/Black</material>
  </gazebo>
  <link name="LARM_JOINT5_Link">
    <visual>
      <origin rpy="0 -0 0" xyz="-0.047 0 -0.09"/>
      <geometry>
        <mesh filename="package://nextage_description/urdf/meshes/LARM_JOINT5_Link_mesh.obj" scale="1 1 1"/>
      </geometry>
    </visual>
    <collision>
      <origin rpy="0 -0 0" xyz="-0.047 0 -0.09"/>
      <geometry>
        <mesh filename="package://nextage_description/urdf/meshes/LARM_JOINT5_Link_mesh.obj" scale="1 1 1"/>
      </geometry>
    </collision>
    <inertial>
      <mass value="1.05156"/>
      <origin rpy="0 -0 0" xyz="-0.048476 -3.2e-06 -0.0388988"/>
      <inertia ixx="0.00194072" ixy="1.1e-07" ixz="-0.00042482" iyy="0.00209392" iyz="1.2e-07" izz="0.00035788"/>
    </inertial>
  </link>
  <gazebo reference="gazebo_RARM_JOINT0_Link">
    <material>Gazebo/Black</material>
  </gazebo>
  <link name="RARM_JOINT0_Link">
    <visual>
      <origin rpy="0.261799 -0 0" xyz="0 -0.145 0.370296"/>
      <geometry>
        <mesh filename="package://nextage_description/urdf/meshes/RARM_JOINT0_Link_mesh.obj" scale="1 1 1"/>
      </geometry>
    </visual>
    <collision>
      <origin rpy="0.261799 -0 0" xyz="0 -0.145 0.370296"/>
      <geometry>
        <mesh filename="package://nextage_description/urdf/meshes/RARM_JOINT0_Link_mesh.obj" scale="1 1 1"/>
      </geometry>
    </collision>
    <inertial>
      <mass value="1.32626"/>
      <origin rpy="0 -0 0" xyz="-0.00226388 0.00521383 0.0156081"/>
      <inertia ixx="0.00207537" ixy="-0.00011276" ixz="8.927e-05" iyy="0.00240295" iyz="4.57e-05" izz="0.00141912"/>
    </inertial>
  </link>
  <gazebo reference="gazebo_RARM_JOINT1_Link">
    <material>Gazebo/Black</material>
  </gazebo>
  <link name="RARM_JOINT1_Link">
    <visual>
      <origin rpy="0 -0 0" xyz="0 0 0"/>
      <geometry>
        <mesh filename="package://nextage_description/urdf/meshes/RARM_JOINT1_Link_mesh.obj" scale="1 1 1"/>
      </geometry>
    </visual>
    <collision>
      <origin rpy="0 -0 0" xyz="0 0 0"/>
      <geometry>
        <mesh filename="package://nextage_description/urdf/meshes/RARM_JOINT1_Link_mesh.obj" scale="1 1 1"/>
      </geometry>
    </collision>
    <inertial>
      <mass value="1.14898"/>
      <origin rpy="0 -0 0" xyz="-5.236e-05 -0.0583134 -0.107061"/>
      <inertia ixx="0.0154168" ixy="-9.95417e-07" ixz="3.38147e-06" iyy="0.0147117" iyz="-0.00213719" izz="0.0012658"/>
    </inertial>
  </link>
  <gazebo reference="gazebo_RARM_JOINT2_Link">
    <material>Gazebo/Black</material>
  </gazebo>
  <link name="RARM_JOINT2_Link">
    <visual>
      <origin rpy="0 -0 0" xyz="0 -0.095 -0.25"/>
      <geometry>
        <mesh filename="package://nextage_description/urdf/meshes/RARM_JOINT2_Link_mesh.obj" scale="1 1 1"/>
      </geometry>
    </visual>
    <collision>
      <origin rpy="0 -0 0" xyz="0 -0.095 -0.25"/>
      <geometry>
        <mesh filename="package://nextage_description/urdf/meshes/RARM_JOINT2_Link_mesh.obj" scale="1 1 1"/>
      </geometry>
    </collision>
    <inertial>
      <mass value="0.577518"/>
      <origin rpy="0 -0 0" xyz="-2.254e-05 -0.00167107 -0.0715116"/>
      <inertia ixx="0.00143966" ixy="3e-07" ixz="1.2e-06" iyy="0.00141763" iyz="7.596e-05" izz="0.0001972"/>
    </inertial>
  </link>
  <gazebo reference="gazebo_RARM_JOINT4_Link">
    <material>Gazebo/Black</material>
  </gazebo>
  <link name="RARM_JOINT3_Link">
    <visual>
      <origin rpy="0 -0 0" xyz="-0.03 0 0"/>
      <geometry>
        <mesh filename="package://nextage_description/urdf/meshes/RARM_JOINT3_Link_mesh.obj" scale="1 1 1"/>
      </geometry>
    </visual>
    <collision>
      <origin rpy="0 -0 0" xyz="-0.03 0 0"/>
      <geometry>
        <mesh filename="package://nextage_description/urdf/meshes/RARM_JOINT3_Link_mesh.obj" scale="1 1 1"/>
      </geometry>
    </collision>
    <inertial>
      <mass value="0.457418"/>
      <origin rpy="0 -0 0" xyz="-1.788e-05 0.00395812 -0.20273"/>
      <inertia ixx="0.00069205" ixy="-3e-08" ixz="5.2e-07" iyy="0.00068903" iyz="1.915e-05" izz="0.00013509"/>
    </inertial>
  </link>
  <gazebo reference="gazebo_RARM_JOINT4_Link">
    <material>Gazebo/Black</material>
  </gazebo>
  <link name="RARM_JOINT4_Link">
    <visual>
      <origin rpy="0 -0 0" xyz="0 0 -0.235"/>
      <geometry>
        <mesh filename="package://nextage_description/urdf/meshes/RARM_JOINT4_Link_mesh.obj" scale="1 1 1"/>
      </geometry>
    </visual>
    <collision>
      <origin rpy="0 -0 0" xyz="0 0 -0.235"/>
      <geometry>
        <mesh filename="package://nextage_description/urdf/meshes/RARM_JOINT4_Link_mesh.obj" scale="1 1 1"/>
      </geometry>
    </collision>
    <inertial>
      <mass value="0.418434"/>
      <origin rpy="0 -0 0" xyz="0.00243131 -0.00379733 -0.0577036"/>
      <inertia ixx="0.00052016" ixy="-1.69e-06" ixz="7.9e-06" iyy="0.00050569" iyz="5.377e-05" izz="0.00014004"/>
    </inertial>
  </link>
  <gazebo reference="gazebo_RARM_JOINT5_Link">
    <material>Gazebo/Black</material>
  </gazebo>
  <link name="RARM_JOINT5_Link">
    <visual>
      <origin rpy="0 -0 0" xyz="-0.047 0 -0.09"/>
      <geometry>
        <mesh filename="package://nextage_description/urdf/meshes/RARM_JOINT5_Link_mesh.obj" scale="1 1 1"/>
      </geometry>
    </visual>
    <collision>
      <origin rpy="0 -0 0" xyz="-0.047 0 -0.09"/>
      <geometry>
        <mesh filename="package://nextage_description/urdf/meshes/RARM_JOINT5_Link_mesh.obj" scale="1 1 1"/>
      </geometry>
    </collision>
    <inertial>
      <mass value="1.05156"/>
      <origin rpy="0 -0 0" xyz="-0.048476 3.2e-06 -0.0388988"/>
      <inertia ixx="0.00194072" ixy="-1.1e-07" ixz="-0.00042482" iyy="0.00209392" iyz="-1.2e-07" izz="0.00035788"/>
    </inertial>
  </link>
  <transmission name="CHEST_JOINT0_Trans">
    <type>transmission_interface/SimpleTransmission</type>
    <joint name="CHEST_JOINT0">
      <hardwareInterface>EffortJointInterface</hardwareInterface>
    </joint>
    <actuator name="CHEST_JOINT0_Motor">
      <hardwareInterface>EffortJointInterface</hardwareInterface>
      <mechanicalReduction>1</mechanicalReduction>
    </actuator>
  </transmission>
  <joint name="CHEST_JOINT0" type="revolute">
    <parent link="WAIST"/>
    <child link="CHEST_JOINT0_Link"/>
    <origin rpy="0 -0 0 " xyz="0 0 0"/>
    <axis xyz="0 0 1"/>
    <limit effort="100" lower="-2.84489" upper="2.84489" velocity="0.5"/>
    <dynamics damping="0.2" friction="0"/>
  </joint>
  <transmission name="HEAD_JOINT0_Trans">
    <type>transmission_interface/SimpleTransmission</type>
    <joint name="HEAD_JOINT0">
      <hardwareInterface>EffortJointInterface</hardwareInterface>
    </joint>
    <actuator name="HEAD_JOINT0_Motor">
      <hardwareInterface>EffortJointInterface</hardwareInterface>
      <mechanicalReduction>1</mechanicalReduction>
    </actuator>
  </transmission>
  <joint name="HEAD_JOINT0" type="revolute">
    <parent link="CHEST_JOINT0_Link"/>
    <child link="HEAD_JOINT0_Link"/>
    <origin rpy="0 -0 0 " xyz="0 0 0.5695"/>
    <axis xyz="0 0 1"/>
    <limit effort="100" lower="-1.22173" upper="1.22173" velocity="0.5"/>
    <dynamics damping="0.2" friction="0"/>
  </joint>
  <transmission name="HEAD_JOINT1_Trans">
    <type>transmission_interface/SimpleTransmission</type>
    <joint name="HEAD_JOINT1">
      <hardwareInterface>EffortJointInterface</hardwareInterface>
    </joint>
    <actuator name="HEAD_JOINT1_Motor">
      <hardwareInterface>EffortJointInterface</hardwareInterface>
      <mechanicalReduction>1</mechanicalReduction>
    </actuator>
  </transmission>
  <joint name="HEAD_JOINT1" type="revolute">
    <parent link="HEAD_JOINT0_Link"/>
    <child link="HEAD_JOINT1_Link"/>
    <origin rpy="0 -0 0 " xyz="0 0 0"/>
    <axis xyz="0 1 0"/>
    <limit effort="100" lower="-0.349066" upper="1.22173" velocity="0.5"/>
    <dynamics damping="0.2" friction="0"/>
  </joint>
  <transmission name="LARM_JOINT0_Trans">
    <type>transmission_interface/SimpleTransmission</type>
    <joint name="LARM_JOINT0">
      <hardwareInterface>EffortJointInterface</hardwareInterface>
    </joint>
    <actuator name="LARM_JOINT0_Motor">
      <hardwareInterface>EffortJointInterface</hardwareInterface>
      <mechanicalReduction>1</mechanicalReduction>
    </actuator>
  </transmission>
  <joint name="LARM_JOINT0" type="revolute">
    <parent link="CHEST_JOINT0_Link"/>
    <child link="LARM_JOINT0_Link"/>
    <origin rpy="-0.261799 0 0 " xyz="0 0.145 0.370296"/>
    <axis xyz="0 0 1"/>
    <limit effort="150" lower="-1.53589" upper="1.53589" velocity="0.5"/>
    <dynamics damping="0.2" friction="0"/>
  </joint>
  <transmission name="LARM_JOINT1_Trans">
    <type>transmission_interface/SimpleTransmission</type>
    <joint name="LARM_JOINT1">
      <hardwareInterface>EffortJointInterface</hardwareInterface>
    </joint>
    <actuator name="LARM_JOINT1_Motor">
      <hardwareInterface>EffortJointInterface</hardwareInterface>
      <mechanicalReduction>1</mechanicalReduction>
    </actuator>
  </transmission>
  <joint name="LARM_JOINT1" type="revolute">
    <parent link="LARM_JOINT0_Link"/>
    <child link="LARM_JOINT1_Link"/>
    <origin rpy="0 -0 0 " xyz="0 0 0"/>
    <axis xyz="0 1 0"/>
    <limit effort="200" lower="-2.44346" upper="1.0472" velocity="0.5"/>
    <dynamics damping="0.2" friction="0"/>
  </joint>
  <transmission name="LARM_JOINT2_Trans">
    <type>transmission_interface/SimpleTransmission</type>
    <joint name="LARM_JOINT2">
      <hardwareInterface>EffortJointInterface</hardwareInterface>
    </joint>
    <actuator name="LARM_JOINT2_Motor">
      <hardwareInterface>EffortJointInterface</hardwareInterface>
      <mechanicalReduction>1</mechanicalReduction>
    </actuator>
  </transmission>
  <joint name="LARM_JOINT2" type="revolute">
    <parent link="LARM_JOINT1_Link"/>
    <child link="LARM_JOINT2_Link"/>
    <origin rpy="0 -0 0 " xyz="0 0.095 -0.25"/>
    <axis xyz="0 1 0"/>
    <limit effort="100" lower="-2.75762" upper="0" velocity="0.5"/>
    <dynamics damping="0.2" friction="0"/>
  </joint>
  <transmission name="LARM_JOINT3_Trans">
    <type>transmission_interface/SimpleTransmission</type>
    <joint name="LARM_JOINT3">
      <hardwareInterface>EffortJointInterface</hardwareInterface>
    </joint>
    <actuator name="LARM_JOINT3_Motor">
      <hardwareInterface>EffortJointInterface</hardwareInterface>
      <mechanicalReduction>1</mechanicalReduction>
    </actuator>
  </transmission>
  <joint name="LARM_JOINT3" type="revolute">
    <parent link="LARM_JOINT2_Link"/>
    <child link="LARM_JOINT3_Link"/>
    <origin rpy="0 -0 0 " xyz="-0.03 0 0"/>
    <axis xyz="0 0 1"/>
    <limit effort="100" lower="-1.8326" upper="2.87979" velocity="0.5"/>
    <dynamics damping="0.2" friction="0"/>
  </joint>
  <transmission name="LARM_JOINT4_Trans">
    <type>transmission_interface/SimpleTransmission</type>
    <joint name="LARM_JOINT4">
      <hardwareInterface>EffortJointInterface</hardwareInterface>
    </joint>
    <actuator name="LARM_JOINT4_Motor">
      <hardwareInterface>EffortJointInterface</hardwareInterface>
      <mechanicalReduction>1</mechanicalReduction>
    </actuator>
  </transmission>
  <joint name="LARM_JOINT4" type="revolute">
    <parent link="LARM_JOINT3_Link"/>
    <child link="LARM_JOINT4_Link"/>
    <origin rpy="0 -0 0 " xyz="0 0 -0.235"/>
    <axis xyz="0 1 0"/>
    <limit effort="100" lower="-1.74533" upper="1.74533" velocity="0.5"/>
    <dynamics damping="0.2" friction="0"/>
  </joint>
  <transmission name="LARM_JOINT5_Trans">
    <type>transmission_interface/SimpleTransmission</type>
    <joint name="LARM_JOINT5">
      <hardwareInterface>EffortJointInterface</hardwareInterface>
    </joint>
    <actuator name="LARM_JOINT5_Motor">
      <hardwareInterface>EffortJointInterface</hardwareInterface>
      <mechanicalReduction>1</mechanicalReduction>
    </actuator>
  </transmission>
  <joint name="LARM_JOINT5" type="revolute">
    <parent link="LARM_JOINT4_Link"/>
    <child link="LARM_JOINT5_Link"/>
    <origin rpy="0 -0 0 " xyz="-0.047 0 -0.09"/>
    <axis xyz="1 0 0"/>
    <limit effort="100" lower="-2.84489" upper="2.84489" velocity="0.5"/>
    <dynamics damping="0.2" friction="0"/>
  </joint>
  <transmission name="RARM_JOINT0_Trans">
    <type>transmission_interface/SimpleTransmission</type>
    <joint name="RARM_JOINT0">
      <hardwareInterface>EffortJointInterface</hardwareInterface>
    </joint>
    <actuator name="RARM_JOINT0_Motor">
      <hardwareInterface>EffortJointInterface</hardwareInterface>
      <mechanicalReduction>1</mechanicalReduction>
    </actuator>
  </transmission>
  <joint name="RARM_JOINT0" type="revolute">
    <parent link="CHEST_JOINT0_Link"/>
    <child link="RARM_JOINT0_Link"/>
    <origin rpy="0.261799 -0 0 " xyz="0 -0.145 0.370296"/>
    <axis xyz="0 0 1"/>
    <limit effort="150" lower="-1.53589" upper="1.53589" velocity="0.5"/>
    <dynamics damping="0.2" friction="0"/>
  </joint>
  <transmission name="RARM_JOINT1_Trans">
    <type>transmission_interface/SimpleTransmission</type>
    <joint name="RARM_JOINT1">
      <hardwareInterface>EffortJointInterface</hardwareInterface>
    </joint>
    <actuator name="RARM_JOINT1_Motor">
      <hardwareInterface>EffortJointInterface</hardwareInterface>
      <mechanicalReduction>1</mechanicalReduction>
    </actuator>
  </transmission>
  <joint name="RARM_JOINT1" type="revolute">
    <parent link="RARM_JOINT0_Link"/>
    <child link="RARM_JOINT1_Link"/>
    <origin rpy="0 -0 0 " xyz="0 0 0"/>
    <axis xyz="0 1 0"/>
    <limit effort="200" lower="-2.44346" upper="1.0472" velocity="0.5"/>
    <dynamics damping="0.2" friction="0"/>
  </joint>
  <transmission name="RARM_JOINT2_Trans">
    <type>transmission_interface/SimpleTransmission</type>
    <joint name="RARM_JOINT2">
      <hardwareInterface>EffortJointInterface</hardwareInterface>
    </joint>
    <actuator name="RARM_JOINT2_Motor">
      <hardwareInterface>EffortJointInterface</hardwareInterface>
      <mechanicalReduction>1</mechanicalReduction>
    </actuator>
  </transmission>
  <joint name="RARM_JOINT2" type="revolute">
    <parent link="RARM_JOINT1_Link"/>
    <child link="RARM_JOINT2_Link"/>
    <origin rpy="0 -0 0 " xyz="0 -0.095 -0.25"/>
    <axis xyz="0 1 0"/>
    <limit effort="100" lower="-2.75762" upper="0" velocity="0.5"/>
    <dynamics damping="0.2" friction="0"/>
  </joint>
  <transmission name="RARM_JOINT3_Trans">
    <type>transmission_interface/SimpleTransmission</type>
    <joint name="RARM_JOINT3">
      <hardwareInterface>EffortJointInterface</hardwareInterface>
    </joint>
    <actuator name="RARM_JOINT3_Motor">
      <hardwareInterface>EffortJointInterface</hardwareInterface>
      <mechanicalReduction>1</mechanicalReduction>
    </actuator>
  </transmission>
  <joint name="RARM_JOINT3" type="revolute">
    <parent link="RARM_JOINT2_Link"/>
    <child link="RARM_JOINT3_Link"/>
    <origin rpy="0 -0 0 " xyz="-0.03 0 0"/>
    <axis xyz="0 0 1"/>
    <limit effort="100" lower="-2.87979" upper="1.8326" velocity="0.5"/>
    <dynamics damping="0.2" friction="0"/>
  </joint>
  <transmission name="RARM_JOINT4_Trans">
    <type>transmission_interface/SimpleTransmission</type>
    <joint name="RARM_JOINT4">
      <hardwareInterface>EffortJointInterface</hardwareInterface>
    </joint>
    <actuator name="RARM_JOINT4_Motor">
      <hardwareInterface>EffortJointInterface</hardwareInterface>
      <mechanicalReduction>1</mechanicalReduction>
    </actuator>
  </transmission>
  <joint name="RARM_JOINT4" type="revolute">
    <parent link="RARM_JOINT3_Link"/>
    <child link="RARM_JOINT4_Link"/>
    <origin rpy="0 -0 0 " xyz="0 0 -0.235"/>
    <axis xyz="0 1 0"/>
    <limit effort="100" lower="-1.74533" upper="1.74533" velocity="0.5"/>
    <dynamics damping="0.2" friction="0"/>
  </joint>
  <transmission name="RARM_JOINT5_Trans">
    <type>transmission_interface/SimpleTransmission</type>
    <joint name="RARM_JOINT5">
      <hardwareInterface>EffortJointInterface</hardwareInterface>
    </joint>
    <actuator name="RARM_JOINT5_Motor">
      <hardwareInterface>EffortJointInterface</hardwareInterface>
      <mechanicalReduction>1</mechanicalReduction>
    </actuator>
  </transmission>
  <joint name="RARM_JOINT5" type="revolute">
    <parent link="RARM_JOINT4_Link"/>
    <child link="RARM_JOINT5_Link"/>
    <origin rpy="0 -0 0 " xyz="-0.047 0 -0.09"/>
    <axis xyz="1 0 0"/>
    <limit effort="100" lower="-2.84489" upper="2.84489" velocity="0.5"/>
    <dynamics damping="0.2" friction="0"/>
  </joint>
  <!-- Gazebo plugin for ROS Control -->
  <gazebo>
    <plugin filename="libgazebo_ros_control.so" name="gazebo_ros_control">
      <robotNamespace>/</robotNamespace>
      <robotSimType>gazebo_ros_control/DefaultRobotHWSim</robotSimType>
    </plugin>
  </gazebo>
</robot>

